#VRML_SIM R2023b utf8

EXTERNPROTO "https://raw.githubusercontent.com/cyberbotics/webots/R2023b/projects/objects/backgrounds/protos/TexturedBackground.proto"
EXTERNPROTO "https://raw.githubusercontent.com/cyberbotics/webots/R2023b/projects/objects/backgrounds/protos/TexturedBackgroundLight.proto"
EXTERNPROTO "https://raw.githubusercontent.com/cyberbotics/webots/R2023b/projects/appearances/protos/BrushedAluminium.proto"
EXTERNPROTO "https://raw.githubusercontent.com/cyberbotics/webots/R2023b/projects/objects/solids/protos/SolidBox.proto"
EXTERNPROTO "https://raw.githubusercontent.com/cyberbotics/webots/R2023b/projects/objects/apartment_structure/protos/Wall.proto"
EXTERNPROTO "https://raw.githubusercontent.com/cyberbotics/webots/R2023b/projects/appearances/protos/Roughcast.proto"

WorldInfo {
}
Viewpoint {
  orientation -0.12443617427347926 0.015379304557897749 0.9921084192382885 2.89760026990617
  position 6.802410274120547 -0.48732709736363555 1.5391559359133913
}
Robot {
  translation 2.72 0.19 0.13
  rotation 0 0 1 3.14159
  children [
    Group {
      children [
        Group {
          children [
            DistanceSensor {
              translation 0 -0.12 0
              rotation 0 0 1 -1.5707953071795862
              name "dist_sen_right"
              lookupTable [
                0 0 0
                0.3 1000 0
              ]
            }
            DistanceSensor {
              translation 0 0.12 0
              rotation 0 0 1 1.5708
              name "dist_sen_left"
              lookupTable [
                0 0 0
                0.3 1000 0
              ]
            }
          ]
        }
        Gyro {
        }
        Compass {
          rotation 0.7071067811862364 0.7071067811862364 0 3.14159
        }
        TouchSensor {
          boundingObject Box {
            size 0.45 0.35 0.08
          }
          physics Physics {
          }
        }
        GPS {
        }
        DEF IMU Pose {
          translation 0 0 0.03
          children [
            Accelerometer {
            }
          ]
        }
        DEF Camera Pose {
          translation 0.0789847 0 0.16955
          rotation 0 1 0 0.1
          children [
            RangeFinder {
              name "depth_Camera"
              width 640
              height 480
            }
            Pose {
              translation -0.005 0 0
              children [
                Shape {
                  appearance PBRAppearance {
                    baseColor 0.141176 0.121569 0.192157
                    roughness 1
                    metalness 0.1
                  }
                  geometry Box {
                    size 0.01 0.06 0.02
                  }
                }
              ]
            }
            Camera {
              fieldOfView 1.5
              width 1280
              height 720
              far 1
            }
          ]
        }
        DEF Lidar Pose {
          translation 0.07 0 0.13
          children [
            Pose {
              translation -0.005 0 0
              children [
                Shape {
                  appearance PBRAppearance {
                    baseColor 0.384314 0.627451 0.917647
                    roughness 1
                    metalness 0.1
                  }
                  geometry Box {
                    size 0.01 0.02 0.02
                  }
                }
              ]
            }
            Lidar {
              horizontalResolution 128
              fieldOfView 6.28
              numberOfLayers 1
              maxRange 1.5
            }
          ]
        }
        Pose {
          children [
            Shape {
              appearance PBRAppearance {
                baseColor 0.560784 0.941176 0.643137
                roughness 0.9
                metalness 0.1
              }
              geometry Box {
                size 0.3 0.13 0.04
              }
            }
          ]
        }
      ]
    }
    Pose {
      translation 0.12 -0.12 -0.06
      rotation 1 0 0 1.5708
      children [
        Hinge2Joint {
          jointParameters HingeJointParameters {
            axis 0 -1 0
            suspensionSpringConstant 1000
            suspensionDampingConstant 5
            suspensionAxis 0 1 0
          }
          jointParameters2 JointParameters {
            axis 0 0 -1
          }
          device [
            RotationalMotor {
              name "right_front_wheel_steering_motor"
              minPosition -1
              maxPosition 1
            }
          ]
          device2 [
            RotationalMotor {
              name "right_front_wheel_motor"
              acceleration 15.6
              maxVelocity 100
              maxTorque 50
            }
          ]
          endPoint Slot {
            endPoint Slot {
              endPoint Solid {
                children [
                  Shape {
                    appearance PBRAppearance {
                      baseColor 0.466667 0.462745 0.482353
                      roughness 0.9
                      metalness 0.1
                    }
                    geometry DEF WHEEL Cylinder {
                      height 0.05
                      radius 0.06
                    }
                  }
                ]
                name "solid(3)"
                boundingObject USE WHEEL
                physics Physics {
                }
              }
            }
          }
        }
      ]
    }
    Pose {
      translation 0.12 0.12 -0.06
      rotation 1 0 0 1.5708
      children [
        Hinge2Joint {
          jointParameters HingeJointParameters {
            axis 0 -1 0
            suspensionSpringConstant 1000
            suspensionDampingConstant 5
            suspensionAxis 0 1 0
          }
          jointParameters2 JointParameters {
            axis 0 0 -1
          }
          device [
            RotationalMotor {
              name "left_front_wheel_steering_motor"
              minPosition -1
              maxPosition 1
            }
          ]
          device2 [
            RotationalMotor {
              name "left_front_wheel_motor"
              acceleration 15.6
              maxVelocity 100
              maxTorque 50
            }
          ]
          endPoint Slot {
            endPoint Slot {
              endPoint Solid {
                children [
                  Shape {
                    appearance PBRAppearance {
                      baseColor 0.466667 0.462745 0.482353
                      roughness 0.9
                      metalness 0.1
                    }
                    geometry DEF WHEEL Cylinder {
                      height 0.05
                      radius 0.06
                    }
                  }
                ]
                name "solid(2)"
                boundingObject USE WHEEL
                physics Physics {
                }
              }
            }
          }
        }
      ]
    }
    Pose {
      translation -0.12 0.12 -0.06
      rotation 1 0 0 1.5708
      children [
        HingeJoint {
          jointParameters HingeJointParameters {
            axis 0 0 -1
            suspensionSpringConstant 1000
            suspensionDampingConstant 5
            suspensionAxis 0 1 0
          }
          device [
            RotationalMotor {
              name "left_rear_wheel_motor"
              acceleration 15.6
              maxVelocity 100
              maxTorque 50
            }
          ]
          endPoint Solid {
            rotation 0 0 -1 0
            children [
              Shape {
                appearance PBRAppearance {
                  baseColor 0.466667 0.462745 0.482353
                  roughness 0.9
                  metalness 0.1
                }
                geometry DEF WHEEL Cylinder {
                  height 0.05
                  radius 0.06
                }
              }
            ]
            name "left_rear_wheel"
            boundingObject USE WHEEL
            physics Physics {
            }
          }
        }
      ]
    }
    Pose {
      translation -0.12 -0.12 -0.06
      rotation 1 0 0 1.5708
      children [
        HingeJoint {
          jointParameters HingeJointParameters {
            axis 0 0 -1
            suspensionSpringConstant 1000
            suspensionDampingConstant 5
            suspensionAxis 0 1 0
          }
          device [
            RotationalMotor {
              name "right_rear_wheel_motor"
              acceleration 15.6
              maxVelocity 100
              maxTorque 50
            }
          ]
          endPoint Solid {
            rotation 0 0 -1 0
            children [
              Shape {
                appearance PBRAppearance {
                  baseColor 0.466667 0.462745 0.482353
                  roughness 0.9
                  metalness 0.1
                }
                geometry DEF WHEEL Cylinder {
                  height 0.05
                  radius 0.06
                }
              }
            ]
            name "right_rear_wheel"
            boundingObject USE WHEEL
            physics Physics {
            }
          }
        }
      ]
    }
  ]
  name "my_car"
  boundingObject Pose {
    translation 0 0 -0.01
    children [
      Box {
        size 0.36 0.24 0.11
      }
    ]
  }
  physics Physics {
    mass 2
  }
  controller "<extern>"
  controllerArgs [
    ""
  ]
  supervisor TRUE
}
TexturedBackground {
}
TexturedBackgroundLight {
}
Solid {
  children [
    Solid {
      children [
        DEF TRACK Shape {
          appearance PBRAppearance {
            baseColorMap ImageTexture {
              url [
                "race track_hq.png"
              ]
            }
            roughness 1
            metalness 0
          }
          geometry Plane {
            size 10.8 7.1
          }
        }
      ]
      boundingObject USE TRACK
    }
    SolidBox {
      translation 5.515 0 0.2
      name "wall"
      size 0.03 11 0.4
      appearance BrushedAluminium {
      }
    }
    SolidBox {
      translation -5.515 0 0.2
      name "wall#2"
      size 0.03 11 0.4
      appearance BrushedAluminium {
      }
    }
    SolidBox {
      translation 0 5.515 0.2
      name "wall#3"
      size 11.06 0.03 0.4
      appearance BrushedAluminium {
      }
    }
    SolidBox {
      translation 0 -5.515 0.2
      name "wall#4"
      size 11.06 0.03 0.4
      appearance BrushedAluminium {
      }
    }
  ]
  name "rectangle arena"
  model "rectangle arena"
}
Wall {
  translation 0.140002 -1.91 -8.96333e-06
  rotation -2.3464099999870814e-06 -2.3464099999870814e-06 0.9999999999944944 -1.5707953071795862
  size 0.1 6 0.1
  appearance Roughcast {
    colorOverride 0 1 1
    textureTransform TextureTransform {
      scale 2.4 1
    }
  }
}
Wall {
  translation 0.140002 -3.37 -1.58144e-05
  rotation -2.3464099999870814e-06 -2.3464099999870814e-06 0.9999999999944944 -1.5707953071795862
  name "wall(9)"
  size 0.1 6 0.1
  appearance Roughcast {
    colorOverride 0 1 1
    textureTransform TextureTransform {
      scale 2.4 1
    }
  }
}
Wall {
  translation 2.16 -0.49 -2.29947e-06
  rotation 2.346409999987081e-06 2.346409999987081e-06 -0.9999999999944942 1.5707953071795862
  name "wall(1)"
  size 0.1 2 0.1
  appearance Roughcast {
    colorOverride 0 1 1
    textureTransform TextureTransform {
      scale 2.4 1
    }
  }
}
Wall {
  translation 2.16 0.9 4.22356e-06
  rotation 2.346409999987081e-06 2.346409999987081e-06 -0.9999999999944942 1.5707953071795862
  name "wall(13)"
  size 0.1 2 0.1
  appearance Roughcast {
    colorOverride 0 1 1
    textureTransform TextureTransform {
      scale 2.4 1
    }
  }
}
Wall {
  translation 3.48777 -1.66369 -7.80771e-06
  rotation -9.719149999968655e-07 2.346409999992433e-06 -0.999999999996775 -2.3561953071795863
  name "wall(6)"
  size 0.1 0.5 0.1
  appearance Roughcast {
    colorOverride 0 1 1
    textureTransform TextureTransform {
      scale 2.4 1
    }
  }
}
Wall {
  translation 3.47362 -0.730381 -3.42768e-06
  rotation 5.664729999893518e-06 -2.3464099999558937e-06 0.9999999999812026 0.785395307179586
  name "wall(7)"
  size 0.1 0.5 0.1
  appearance Roughcast {
    colorOverride 0 1 1
    textureTransform TextureTransform {
      scale 2.4 1
    }
  }
}
Wall {
  translation 3.68007 -1.18685 -5.55155e-06
  rotation -0.8528617280168679 2.507359200386902e-07 0.52213683348718 -5.307179586466759e-06
  name "wall(8)"
  size 0.1 0.5 0.1
  appearance Roughcast {
    colorOverride 0 1 1
    textureTransform TextureTransform {
      scale 2.4 1
    }
  }
}
Wall {
  translation -2.43 1.85 8.68174e-06
  rotation 2.346409999987081e-06 2.346409999987081e-06 -0.9999999999944942 1.5707953071795862
  name "wall(5)"
  size 0.1 2 0.1
  appearance Roughcast {
    colorOverride 0 1 1
    textureTransform TextureTransform {
      scale 2.4 1
    }
  }
}
Wall {
  translation -2.43 3.27 1.53459e-05
  rotation 2.346409999987081e-06 2.346409999987081e-06 -0.9999999999944942 1.5707953071795862
  name "wall(15)"
  size 0.1 3 0.1
  appearance Roughcast {
    colorOverride 0 1 1
    textureTransform TextureTransform {
      scale 2.4 1
    }
  }
}
Wall {
  translation -3.33975 -0.100155 -4.50967e-07
  rotation -3.089109999991349e-07 -2.346409999993429e-06 0.9999999999971996 -2.95
  name "wall(4)"
  size 0.1 3.5 0.1
  appearance Roughcast {
    colorOverride 0 1 1
    textureTransform TextureTransform {
      scale 2.4 1
    }
  }
}
Wall {
  translation -4.82222 -0.387684 -2.05004e-06
  rotation -3.089109999991349e-07 -2.346409999993429e-06 0.9999999999971996 -2.95
  name "wall(16)"
  size 0.1 3.5 0.1
  appearance Roughcast {
    colorOverride 0 1 1
    textureTransform TextureTransform {
      scale 2.4 1
    }
  }
}
Wall {
  translation 0.322614 -0.162417 -7.62242e-07
  rotation -1.3546999999950276e-06 -2.3464099999913877e-06 0.9999999999963296 -2.094395307179586
  name "wall(2)"
  size 0.1 1.5 0.1
  appearance Roughcast {
    colorOverride 0 1 1
    textureTransform TextureTransform {
      scale 2.4 1
    }
  }
}
Wall {
  translation 4.23296 0.57057 2.67761e-06
  rotation -1.3546999999950276e-06 -2.3464099999913877e-06 0.9999999999963296 -2.094395307179586
  name "wall(12)"
  size 0.1 1.5 0.1
  appearance Roughcast {
    colorOverride 0 1 1
    textureTransform TextureTransform {
      scale 2.4 1
    }
  }
}
Wall {
  translation 4.34037 -3.06981 -1.45973e-05
  rotation 3.0578999999772855e-06 2.3464099999825706e-06 -0.9999999999925719 1.0472003061004251
  name "wall(11)"
  size 0.1 1.8 0.1
  appearance Roughcast {
    colorOverride 0 1 1
    textureTransform TextureTransform {
      scale 2.4 1
    }
  }
}
Wall {
  translation 5.17304 -1.26177 -5.92118e-06
  rotation 3.5259799999902937e-13 -2.346409999993541e-06 0.9999999999972473 3.14159
  name "wall(10)"
  size 0.1 2.6 0.1
  appearance Roughcast {
    colorOverride 0 1 1
    textureTransform TextureTransform {
      scale 2.4 1
    }
  }
}
Wall {
  translation -3.88054 -2.91648 -1.36861e-05
  rotation -9.719139999968655e-07 -2.346409999992433e-06 0.999999999996775 -2.2253003061004253
  name "wall(17)"
  size 0.1 1.5 0.1
  appearance Roughcast {
    colorOverride 0 1 1
    textureTransform TextureTransform {
      scale 2.4 1
    }
  }
}
Wall {
  translation -0.790186 1.05667 4.80466e-06
  rotation 5.664749999787036e-06 -2.3464099999117874e-06 0.9999999999812026 0.6545003061004253
  name "wall(3)"
  size 0.1 1.5 0.1
  appearance Roughcast {
    colorOverride 0 1 1
    textureTransform TextureTransform {
      scale 2.4 1
    }
  }
}
Wall {
  translation -4.89527 2.54453 9.59788e-06
  rotation 5.38698e-07 -2.01044e-06 1 2.4871
  name "wall(18)"
  size 0.1 1.5 0.1
  appearance Roughcast {
    colorOverride 0 1 1
    textureTransform TextureTransform {
      scale 2.4 1
    }
  }
}
Wall {
  translation 0.398556 1.90591 8.45101e-06
  rotation 5.664749999787036e-06 -2.3464099999117874e-06 0.9999999999812026 0.6545003061004253
  name "wall(14)"
  size 0.1 2.2 0.1
  appearance Roughcast {
    colorOverride 0 1 1
    textureTransform TextureTransform {
      scale 2.4 1
    }
  }
}
